### **任务中的异常处理**

在 **C#** 中，当使用任务（Task）时，异常处理非常重要，以确保应用程序在任务执行失败时能够正确响应。任务可能会在执行过程中抛出异常，C# 提供了一些机制来处理这些异常。

---

### **任务中的异常类型**

1. **同步异常**：
   - 在启动任务或立即执行任务时发生的异常。

2. **异步异常**：
   - 在任务执行过程中（如 `Task.Run` 或异步方法中）抛出的异常。

---

### **使用 `try-catch` 处理异常**

可以使用 `try-catch` 块捕获任务中抛出的异常：

#### **示例：单任务中的异常处理**

```csharp
using System;
using System.Threading.Tasks;

class Program
{
    static async Task Main()
    {
        try
        {
            await Task.Run(() =>
            {
                Console.WriteLine("任务正在运行...");
                throw new InvalidOperationException("任务中发生了错误。");
            });
        }
        catch (Exception ex)
        {
            Console.WriteLine($"捕获的异常：{ex.Message}");
        }
    }
}
```

#### **输出**：
```
任务正在运行...
捕获的异常：任务中发生了错误。
```

---

### **通过 `Task.Wait` 或 `Task.Result` 捕获异常**

当使用 `Task.Wait()` 或访问 `Task.Result` 时，异常会被包装在 **`AggregateException`** 中，其中包含所有任务抛出的异常。

#### **示例：使用 `Task.Wait`**

```csharp
using System;
using System.Threading.Tasks;

class Program
{
    static void Main()
    {
        Task task = Task.Run(() =>
        {
            Console.WriteLine("任务正在运行...");
            throw new InvalidOperationException("任务失败。");
        });

        try
        {
            task.Wait(); // 阻塞并等待任务完成
        }
        catch (AggregateException ex)
        {
            foreach (var innerException in ex.InnerExceptions)
            {
                Console.WriteLine($"捕获的异常：{innerException.Message}");
            }
        }
    }
}
```

#### **输出**：
```
任务正在运行...
捕获的异常：任务失败。
```

---

### **处理多个任务中的异常**

当多个任务并发运行时，可以使用 **`Task.WhenAll`** 或 **`Task.WaitAll`**。如果任意任务抛出异常，所有异常会被捕获到 **`AggregateException`** 中。

#### **示例：使用 `Task.WhenAll`**

```csharp
using System;
using System.Threading.Tasks;

class Program
{
    static async Task Main()
    {
        Task task1 = Task.Run(() =>
        {
            Console.WriteLine("任务 1 正在运行...");
            throw new InvalidOperationException("任务 1 失败。");
        });

        Task task2 = Task.Run(() =>
        {
            Console.WriteLine("任务 2 正在运行...");
            throw new ArgumentException("任务 2 失败。");
        });

        try
        {
            await Task.WhenAll(task1, task2);
        }
        catch (AggregateException ex)
        {
            foreach (var innerException in ex.InnerExceptions)
            {
                Console.WriteLine($"捕获的异常：{innerException.Message}");
            }
        }
    }
}
```

#### **输出**：
```
任务 1 正在运行...
任务 2 正在运行...
捕获的异常：任务 1 失败。
捕获的异常：任务 2 失败。
```

---

### **任务异常处理的最佳实践**

1. **优先使用 `await`**：
   - 在任务上使用 `await` 会自动解包异常，可以直接在 `try-catch` 中处理。

   ```csharp
   try
   {
       await Task.Run(() => { throw new InvalidOperationException("发生错误"); });
   }
   catch (Exception ex)
   {
       Console.WriteLine($"异常：{ex.Message}");
   }
   ```

2. **处理 `AggregateException`**：
   - 当使用 `Task.Wait`、`Task.Result`、`Task.WhenAll` 或 `Task.WaitAll` 时，需要通过 `AggregateException` 捕获异常。

3. **使用 `ContinueWith` 进行后续处理**：
   - 可以在任务完成后附加一个延续任务，处理异常或执行清理操作。

   ```csharp
   Task.Run(() => { throw new InvalidOperationException("任务错误"); })
       .ContinueWith(t =>
       {
           if (t.IsFaulted)
           {
               Console.WriteLine($"处理异常：{t.Exception?.InnerException?.Message}");
           }
       });
   ```

4. **结合任务取消和异常处理**：
   - 使用 `CancellationToken` 优雅地停止任务，同时处理异常。

   ```csharp
   using System.Threading;

   CancellationTokenSource cts = new CancellationTokenSource();
   Task.Run(() =>
   {
       throw new InvalidOperationException("任务失败");
   }, cts.Token).ContinueWith(t =>
   {
       if (t.IsCanceled)
           Console.WriteLine("任务已取消。");
       else if (t.IsFaulted)
           Console.WriteLine($"异常：{t.Exception?.InnerException?.Message}");
   });
   ```

5. **记录异常**：
   - 始终记录异常以便调试和监控。

---

### **不同异常处理方法的对比**

| **方法**                   | **行为**                                                         | **适用场景**                                |
|----------------------------|-----------------------------------------------------------------|---------------------------------------------|
| `try-catch` with `await`   | 异常会自动解包，直接在 `try-catch` 中捕获                         | 简单的异步任务                               |
| `AggregateException`       | 捕获所有任务的异常，并包装到一个 `AggregateException` 对象中       | 处理多个任务或阻塞调用（如 `Task.Wait`）      |
| `ContinueWith`             | 附加延续任务处理异常或执行清理                                   | 任务特定的清理或日志记录                     |
| 结合取消处理               | 优雅地停止任务，同时处理异常                                     | 可取消的任务操作                             |

---

### **总结**

1. 使用 **`await`** 结合 `try-catch` 是处理任务异常的首选方式。
2. 在需要处理多个任务或阻塞任务时，使用 **`AggregateException`**。
3. 使用 **`ContinueWith`** 可以添加任务完成后的自定义处理逻辑。
4. 结合 **取消令牌（CancellationToken）** 和异常处理以实现更优雅的任务管理。
5. 始终记录异常以帮助调试和监控。

通过应用这些最佳实践，可以高效地处理任务中的异常，并确保应用程序的可靠性和健壮性。
