# exception handling

In Python, the `try...except` block is used for exception handling, allowing you to catch and respond to errors or exceptions that occur during the execution of your program. This mechanism helps to make the program more robust and prevents it from crashing unexpectedly.

### Basic Structure

The basic structure of a `try...except` block is as follows:

```python
try:
    # Code that might cause an exception
    risky_operation()
except SomeException as e:
    # Code that runs if an exception occurs
    print("An error occurred:", e)
```

1. **`try` Block**: You put the code that might cause an exception inside the `try` block.
   
   **`try` 块**：你将可能引发异常的代码放在 `try` 块中。

2. **`except` Block**: Code inside the `except` block runs if an exception of the matching type is thrown in the `try` block.
   
   **`except` 块**：如果 `try` 块中抛出匹配类型的异常，则 `except` 块中的代码将运行。

### Common Python Exceptions

Here is a list of some common exceptions in Python along with their typical causes:

| Exception              | Description (EN)                                      | Description (CN)                              |
|------------------------|-------------------------------------------------------|-----------------------------------------------|
| `Exception`            | Base class for all built-in exceptions                | 所有内置异常的基类                            |
| `AttributeError`       | Raised when an attribute reference or assignment fails| 当属性引用或赋值失败时引发                     |
| `IOError`              | Raised when an I/O operation fails                    | 当 I/O 操作失败时引发                         |
| `ImportError`          | Raised when an import statement fails                 | 当导入语句失败时引发                          |
| `IndexError`           | Raised when a sequence subscript is out of range      | 当序列下标超出范围时引发                      |
| `KeyError`             | Raised when a dictionary key is not found             | 当字典键找不到时引发                          |
| `KeyboardInterrupt`    | Raised when the user hits the interrupt key (Ctrl+C)  | 当用户按下中断键（Ctrl+C）时引发              |
| `NameError`            | Raised when a local or global name is not found       | 当找不到本地或全局名称时引发                  |
| `SyntaxError`          | Raised when there is an error in Python syntax        | 当 Python 语法错误时引发                      |
| `TypeError`            | Raised when an operation or function is applied to an object of inappropriate type | 当操作或函数应用于不适当类型的对象时引发      |
| `ValueError`           | Raised when a function gets an argument of correct type but improper value | 当函数获得正确类型但不当值的参数时引发        |
| `ZeroDivisionError`    | Raised when the second argument of a division or modulo operation is zero | 当除法或模运算的第二个参数为零时引发          |

### Example with Code

Here's a practical example demonstrating the use of `try...except`:

```python
try:
    # This will raise a ZeroDivisionError
    result = 10 / 0
except ZeroDivisionError as e:
    print("Caught an error:", e)
```

### Explanation | 解释

- The code attempts to divide 10 by zero, which raises a `ZeroDivisionError`.
  
  代码试图将10除以零，这会引发 `ZeroDivisionError`。

- The `except` block catches the error and prints a message.

  `except` 块捕获错误并打印消息。

Using `try...except` blocks appropriately can help in handling errors gracefully and maintaining a smooth user experience in your applications.
